<?xml version="1.0" ?>
<!-- =================================================================================== -->
<!-- |    This document was autogenerated by xacro from /home/khushi22/Sure_Trust/src/urdf_launch_new/models/hand.urdf.xacro | -->
<!-- |    EDITING THIS FILE BY HAND IS NOT RECOMMENDED                                 | -->
<!-- =================================================================================== -->
<robot name="human_hand">
  <!-- Materials -->
  <material name="skin">
    <color rgba="1 0.8 0.6 1"/>
  </material>
  <!-- Palm -->
  <link name="palm">
    <visual>
      <geometry>
        <box size="0.1 0.2 0.02"/>
      </geometry>
      <material name="skin"/>
    </visual>
    <collision>
      <geometry>
        <box size="0.1 0.2 0.02"/>
      </geometry>
    </collision>
    <inertial>
      <mass value="0.2"/>
      <origin rpy="0 0 0" xyz="0 0 0"/>
      <inertia ixx="0.0002" ixy="0.0" ixz="0.0" iyy="0.0002" iyz="0.0" izz="0.0002"/>
    </inertial>
  </link>
  <!-- Proximal Phalanx -->
  <link name="thumb_proximal">
    <visual>
      <geometry>
        <cylinder length="0.05" radius="0.015"/>
      </geometry>
      <material name="skin"/>
    </visual>
    <collision>
      <geometry>
        <cylinder length="0.05" radius="0.015"/>
      </geometry>
    </collision>
    <inertial>
      <mass value="0.05"/>
      <origin rpy="0 0 0" xyz="0 0 0"/>
      <inertia ixx="0.00005" ixy="0.0" ixz="0.0" iyy="0.00005" iyz="0.0" izz="0.00005"/>
    </inertial>
  </link>
  <joint name="thumb_knuckle" type="revolute">
    <parent link="palm"/>
    <child link="thumb_proximal"/>
    <origin rpy="0 0 0" xyz="0.05 0.1 0.02"/>
    <axis xyz="0 1 0"/>
    <limit effort="10.0" lower="0" upper="1.5" velocity="1.0"/>
  </joint>
  <!-- Intermediate Phalanx -->
  <link name="thumb_intermediate">
    <visual>
      <geometry>
        <cylinder length="0.04" radius="0.012"/>
      </geometry>
      <material name="skin"/>
    </visual>
    <collision>
      <geometry>
        <cylinder length="0.04" radius="0.012"/>
      </geometry>
    </collision>
    <inertial>
      <mass value="0.03"/>
      <origin rpy="0 0 0" xyz="0 0 0"/>
      <inertia ixx="0.00003" ixy="0.0" ixz="0.0" iyy="0.00003" iyz="0.0" izz="0.00003"/>
    </inertial>
  </link>
  <joint name="thumb_middle" type="revolute">
    <parent link="thumb_proximal"/>
    <child link="thumb_intermediate"/>
    <origin rpy="0 0 0" xyz="0 0 -0.05"/>
    <axis xyz="0 1 0"/>
    <limit effort="5.0" lower="0" upper="1.0" velocity="0.5"/>
    <mimic joint="thumb_knuckle" multiplier="0.7" offset="0"/>
  </joint>
  <!-- Distal Phalanx -->
  <link name="thumb_distal">
    <visual>
      <geometry>
        <cylinder length="0.03" radius="0.01"/>
      </geometry>
      <material name="skin"/>
    </visual>
    <collision>
      <geometry>
        <cylinder length="0.03" radius="0.01"/>
      </geometry>
    </collision>
    <inertial>
      <mass value="0.02"/>
      <origin rpy="0 0 0" xyz="0 0 0"/>
      <inertia ixx="0.00002" ixy="0.0" ixz="0.0" iyy="0.00002" iyz="0.0" izz="0.00002"/>
    </inertial>
  </link>
  <joint name="thumb_tip" type="revolute">
    <parent link="thumb_intermediate"/>
    <child link="thumb_distal"/>
    <origin rpy="0 0 0" xyz="0 0 -0.04"/>
    <axis xyz="0 1 0"/>
    <limit effort="2.0" lower="0" upper="1.0" velocity="0.5"/>
    <mimic joint="thumb_middle" multiplier="0.7" offset="0"/>
  </joint>
  <!-- Proximal Phalanx -->
  <link name="index_proximal">
    <visual>
      <geometry>
        <cylinder length="0.05" radius="0.015"/>
      </geometry>
      <material name="skin"/>
    </visual>
    <collision>
      <geometry>
        <cylinder length="0.05" radius="0.015"/>
      </geometry>
    </collision>
    <inertial>
      <mass value="0.05"/>
      <origin rpy="0 0 0" xyz="0 0 0"/>
      <inertia ixx="0.00005" ixy="0.0" ixz="0.0" iyy="0.00005" iyz="0.0" izz="0.00005"/>
    </inertial>
  </link>
  <joint name="index_knuckle" type="revolute">
    <parent link="palm"/>
    <child link="index_proximal"/>
    <origin rpy="0 0 0" xyz="0.05 0.05 0.02"/>
    <axis xyz="0 1 0"/>
    <limit effort="10.0" lower="0" upper="1.5" velocity="1.0"/>
  </joint>
  <!-- Intermediate Phalanx -->
  <link name="index_intermediate">
    <visual>
      <geometry>
        <cylinder length="0.04" radius="0.012"/>
      </geometry>
      <material name="skin"/>
    </visual>
    <collision>
      <geometry>
        <cylinder length="0.04" radius="0.012"/>
      </geometry>
    </collision>
    <inertial>
      <mass value="0.03"/>
      <origin rpy="0 0 0" xyz="0 0 0"/>
      <inertia ixx="0.00003" ixy="0.0" ixz="0.0" iyy="0.00003" iyz="0.0" izz="0.00003"/>
    </inertial>
  </link>
  <joint name="index_middle" type="revolute">
    <parent link="index_proximal"/>
    <child link="index_intermediate"/>
    <origin rpy="0 0 0" xyz="0 0 -0.05"/>
    <axis xyz="0 1 0"/>
    <limit effort="5.0" lower="0" upper="1.0" velocity="0.5"/>
    <mimic joint="index_knuckle" multiplier="0.7" offset="0"/>
  </joint>
  <!-- Distal Phalanx -->
  <link name="index_distal">
    <visual>
      <geometry>
        <cylinder length="0.03" radius="0.01"/>
      </geometry>
      <material name="skin"/>
    </visual>
    <collision>
      <geometry>
        <cylinder length="0.03" radius="0.01"/>
      </geometry>
    </collision>
    <inertial>
      <mass value="0.02"/>
      <origin rpy="0 0 0" xyz="0 0 0"/>
      <inertia ixx="0.00002" ixy="0.0" ixz="0.0" iyy="0.00002" iyz="0.0" izz="0.00002"/>
    </inertial>
  </link>
  <joint name="index_tip" type="revolute">
    <parent link="index_intermediate"/>
    <child link="index_distal"/>
    <origin rpy="0 0 0" xyz="0 0 -0.04"/>
    <axis xyz="0 1 0"/>
    <limit effort="2.0" lower="0" upper="1.0" velocity="0.5"/>
    <mimic joint="index_middle" multiplier="0.7" offset="0"/>
  </joint>
  <!-- Proximal Phalanx -->
  <link name="middle_proximal">
    <visual>
      <geometry>
        <cylinder length="0.05" radius="0.015"/>
      </geometry>
      <material name="skin"/>
    </visual>
    <collision>
      <geometry>
        <cylinder length="0.05" radius="0.015"/>
      </geometry>
    </collision>
    <inertial>
      <mass value="0.05"/>
      <origin rpy="0 0 0" xyz="0 0 0"/>
      <inertia ixx="0.00005" ixy="0.0" ixz="0.0" iyy="0.00005" iyz="0.0" izz="0.00005"/>
    </inertial>
  </link>
  <joint name="middle_knuckle" type="revolute">
    <parent link="palm"/>
    <child link="middle_proximal"/>
    <origin rpy="0 0 0" xyz="0.05 0 0.02"/>
    <axis xyz="0 1 0"/>
    <limit effort="10.0" lower="0" upper="1.5" velocity="1.0"/>
  </joint>
  <!-- Intermediate Phalanx -->
  <link name="middle_intermediate">
    <visual>
      <geometry>
        <cylinder length="0.04" radius="0.012"/>
      </geometry>
      <material name="skin"/>
    </visual>
    <collision>
      <geometry>
        <cylinder length="0.04" radius="0.012"/>
      </geometry>
    </collision>
    <inertial>
      <mass value="0.03"/>
      <origin rpy="0 0 0" xyz="0 0 0"/>
      <inertia ixx="0.00003" ixy="0.0" ixz="0.0" iyy="0.00003" iyz="0.0" izz="0.00003"/>
    </inertial>
  </link>
  <joint name="middle_middle" type="revolute">
    <parent link="middle_proximal"/>
    <child link="middle_intermediate"/>
    <origin rpy="0 0 0" xyz="0 0 -0.05"/>
    <axis xyz="0 1 0"/>
    <limit effort="5.0" lower="0" upper="1.0" velocity="0.5"/>
    <mimic joint="middle_knuckle" multiplier="0.7" offset="0"/>
  </joint>
  <!-- Distal Phalanx -->
  <link name="middle_distal">
    <visual>
      <geometry>
        <cylinder length="0.03" radius="0.01"/>
      </geometry>
      <material name="skin"/>
    </visual>
    <collision>
      <geometry>
        <cylinder length="0.03" radius="0.01"/>
      </geometry>
    </collision>
    <inertial>
      <mass value="0.02"/>
      <origin rpy="0 0 0" xyz="0 0 0"/>
      <inertia ixx="0.00002" ixy="0.0" ixz="0.0" iyy="0.00002" iyz="0.0" izz="0.00002"/>
    </inertial>
  </link>
  <joint name="middle_tip" type="revolute">
    <parent link="middle_intermediate"/>
    <child link="middle_distal"/>
    <origin rpy="0 0 0" xyz="0 0 -0.04"/>
    <axis xyz="0 1 0"/>
    <limit effort="2.0" lower="0" upper="1.0" velocity="0.5"/>
    <mimic joint="middle_middle" multiplier="0.7" offset="0"/>
  </joint>
  <!-- Proximal Phalanx -->
  <link name="ring_proximal">
    <visual>
      <geometry>
        <cylinder length="0.05" radius="0.015"/>
      </geometry>
      <material name="skin"/>
    </visual>
    <collision>
      <geometry>
        <cylinder length="0.05" radius="0.015"/>
      </geometry>
    </collision>
    <inertial>
      <mass value="0.05"/>
      <origin rpy="0 0 0" xyz="0 0 0"/>
      <inertia ixx="0.00005" ixy="0.0" ixz="0.0" iyy="0.00005" iyz="0.0" izz="0.00005"/>
    </inertial>
  </link>
  <joint name="ring_knuckle" type="revolute">
    <parent link="palm"/>
    <child link="ring_proximal"/>
    <origin rpy="0 0 0" xyz="0.05 -0.05 0.02"/>
    <axis xyz="0 1 0"/>
    <limit effort="10.0" lower="0" upper="1.5" velocity="1.0"/>
  </joint>
  <!-- Intermediate Phalanx -->
  <link name="ring_intermediate">
    <visual>
      <geometry>
        <cylinder length="0.04" radius="0.012"/>
      </geometry>
      <material name="skin"/>
    </visual>
    <collision>
      <geometry>
        <cylinder length="0.04" radius="0.012"/>
      </geometry>
    </collision>
    <inertial>
      <mass value="0.03"/>
      <origin rpy="0 0 0" xyz="0 0 0"/>
      <inertia ixx="0.00003" ixy="0.0" ixz="0.0" iyy="0.00003" iyz="0.0" izz="0.00003"/>
    </inertial>
  </link>
  <joint name="ring_middle" type="revolute">
    <parent link="ring_proximal"/>
    <child link="ring_intermediate"/>
    <origin rpy="0 0 0" xyz="0 0 -0.05"/>
    <axis xyz="0 1 0"/>
    <limit effort="5.0" lower="0" upper="1.0" velocity="0.5"/>
    <mimic joint="ring_knuckle" multiplier="0.7" offset="0"/>
  </joint>
  <!-- Distal Phalanx -->
  <link name="ring_distal">
    <visual>
      <geometry>
        <cylinder length="0.03" radius="0.01"/>
      </geometry>
      <material name="skin"/>
    </visual>
    <collision>
      <geometry>
        <cylinder length="0.03" radius="0.01"/>
      </geometry>
    </collision>
    <inertial>
      <mass value="0.02"/>
      <origin rpy="0 0 0" xyz="0 0 0"/>
      <inertia ixx="0.00002" ixy="0.0" ixz="0.0" iyy="0.00002" iyz="0.0" izz="0.00002"/>
    </inertial>
  </link>
  <joint name="ring_tip" type="revolute">
    <parent link="ring_intermediate"/>
    <child link="ring_distal"/>
    <origin rpy="0 0 0" xyz="0 0 -0.04"/>
    <axis xyz="0 1 0"/>
    <limit effort="2.0" lower="0" upper="1.0" velocity="0.5"/>
    <mimic joint="ring_middle" multiplier="0.7" offset="0"/>
  </joint>
  <!-- Proximal Phalanx -->
  <link name="pinky_proximal">
    <visual>
      <geometry>
        <cylinder length="0.05" radius="0.015"/>
      </geometry>
      <material name="skin"/>
    </visual>
    <collision>
      <geometry>
        <cylinder length="0.05" radius="0.015"/>
      </geometry>
    </collision>
    <inertial>
      <mass value="0.05"/>
      <origin rpy="0 0 0" xyz="0 0 0"/>
      <inertia ixx="0.00005" ixy="0.0" ixz="0.0" iyy="0.00005" iyz="0.0" izz="0.00005"/>
    </inertial>
  </link>
  <joint name="pinky_knuckle" type="revolute">
    <parent link="palm"/>
    <child link="pinky_proximal"/>
    <origin rpy="0 0 0" xyz="0.05 -0.1 0.02"/>
    <axis xyz="0 1 0"/>
    <limit effort="10.0" lower="0" upper="1.5" velocity="1.0"/>
  </joint>
  <!-- Intermediate Phalanx -->
  <link name="pinky_intermediate">
    <visual>
      <geometry>
        <cylinder length="0.04" radius="0.012"/>
      </geometry>
      <material name="skin"/>
    </visual>
    <collision>
      <geometry>
        <cylinder length="0.04" radius="0.012"/>
      </geometry>
    </collision>
    <inertial>
      <mass value="0.03"/>
      <origin rpy="0 0 0" xyz="0 0 0"/>
      <inertia ixx="0.00003" ixy="0.0" ixz="0.0" iyy="0.00003" iyz="0.0" izz="0.00003"/>
    </inertial>
  </link>
  <joint name="pinky_middle" type="revolute">
    <parent link="pinky_proximal"/>
    <child link="pinky_intermediate"/>
    <origin rpy="0 0 0" xyz="0 0 -0.05"/>
    <axis xyz="0 1 0"/>
    <limit effort="5.0" lower="0" upper="1.0" velocity="0.5"/>
    <mimic joint="pinky_knuckle" multiplier="0.7" offset="0"/>
  </joint>
  <!-- Distal Phalanx -->
  <link name="pinky_distal">
    <visual>
      <geometry>
        <cylinder length="0.03" radius="0.01"/>
      </geometry>
      <material name="skin"/>
    </visual>
    <collision>
      <geometry>
        <cylinder length="0.03" radius="0.01"/>
      </geometry>
    </collision>
    <inertial>
      <mass value="0.02"/>
      <origin rpy="0 0 0" xyz="0 0 0"/>
      <inertia ixx="0.00002" ixy="0.0" ixz="0.0" iyy="0.00002" iyz="0.0" izz="0.00002"/>
    </inertial>
  </link>
  <joint name="pinky_tip" type="revolute">
    <parent link="pinky_intermediate"/>
    <child link="pinky_distal"/>
    <origin rpy="0 0 0" xyz="0 0 -0.04"/>
    <axis xyz="0 1 0"/>
    <limit effort="2.0" lower="0" upper="1.0" velocity="0.5"/>
    <mimic joint="pinky_middle" multiplier="0.7" offset="0"/>
  </joint>
</robot>
